Workbook

Sheet Master Data
B1: Author | C1: Application No. | D1: Branch | E1: Applicant | F1: Co-Applicants | G1: Transaction Type | H1: Property Details | I1: TSR | J1: Vet + CTC | K1: CTC
A2: 1 | B2: Adv. Narayan | C2: .
A3: =A2+1 -> 2 | B3: Adv. Narayan | C3: 77000234182 | D3: Main | E3: Swapan Mandol | F3: ABC | G3: Resale | H3: Pune. Ganesh Peth. CTS No. 48 | I3: 99
A4: =A3+1 -> 3 | B4: Adv. Narayan | C4: 7792016425 | D4: Main | E4: Aahan Buildcon | I4: 99
A5: =A4+1 -> 4 | B5: Adv. Narayan | C5: 77000250964 | D5: Baner | E5: Santosh Ghumare | I5: 99
A6: =A5+1 -> 5 | B6: Adv. Narayan | C6: 7792144896 | D6: Wakad | E6: Dattatray Suresh Kalbhor | F6: Mrs. Deepali Dattatray Kalbhor | G6: Builder Purchase | H6: All that residential Apartment No. 2405 on the 24th Floor, admeasuring 55.76 Sq. Mtrs. carpet area, along with appurtenant area of 9.14 Sq. Mtrs., including attached balcony admeasuring 2.60 Sq. Mtrs., in the Building No. G, known as “Giardino” in the project known as “Puraniks Abitante Fiore, Phase 2B”, to be constructed on the aforesaid entire land property, i.e. Survey No. 233/1 to 7/235/1/235/2A/235/2B/244/2 and others, situated at Village – Bavdhan Budruk, Taluka – Mulshi, District – Pune. | I6: 99
A7: =A6+1 -> 6 | B7: Adv. Narayan | C7: APF | D7: Main | E7: Tathastu | I7: 99
A8: =A7+1 -> 7 | B8: Adv. Narayan | C8: 77000238463 | D8: Main | E8: Pradeep Patil | G8: Resale | H8: All that piece and parcel of property bearing Flat No. 704, having built-up area admeasuring of 601 sq. feets., i.e. 55.85 sq. mtrs., along with terrace area admeasuring of 74 sq. feets., i.e. 6.87 sq. mtrs., i.e. total saleable area admeasuring of 638 sq. feets., i.e. 59.29 sq.mtrs., situated on the Seventh Floor, along with one two wheeler parking space, in Building No. "K-2", out of the project known as "Kate Puram-II", constructed on the land bearing No. Plot No. 3+4, out of the Survey No. 48/1/1 + 48/2/1, situated at Village - Pimpale Gurav, Taluka - Haveli, District - Pune and within local limits of Pimpri Chinchwad Municipal Corporation, Pimpri. | I8: 99
A9: =A8+1 -> 8 | B9: Adv. Narayan | C9: 77000249933 | D9: Main | E9: Swapnil Mardane | G9: BT Top UP | H9: All that residential Flat/Apartment No. 108, having built-up area admeasuring 1059.50 Sq. Feet (i.e. 98.46 Sq. Mtrs.), along with adjoining terrace area admeasuring 62.88 Sq. Feet (i.e. 5.84 Sq. Mtrs.), aggregating to total saleable area of 1100 Sq. Feet (i.e. 102.23 Sq. Mtrs.), situated on the First Floor, in Wing B-2 of the building known as “Sneha Vihar B-2 Co-operative Housing Society Ltd.”, constructed on land bearing Survey No. 82, Hissa No. 10, situated at Village – Shivane, Taluka – Haveli, District – Pune, within the limits of Pune Municipal Corporation. | I9: 99
A10: =A9+1 -> 9 | B10: Adv. Narayan | C10: 77000251190_1 | D10: Baner | E10: VRINDA MANISH BUTTAN | G10: BT Top UP | H10: All that residential Flat/Apartment No. 701, admeasuring 92.44 Sq. Mtrs. (i.e. approximately 995.01 Sq. Feet), situated on the 7th Floor, in “D” Building of the project known as “Maestros”, constructed on land bearing Survey No. 60/7, situated at Village – Wanawadi (Wanorie), Taluka – Haveli, District – Pune, within the limits of Pune Municipal Corporation, along with the right to use one car parking space, together with all easements, rights and appurtenances thereto. | I10: 99
A11: =A10+1 -> 10 | B11: Adv. Narayan | C11: 77000251190_2 | D11: Baner | E11: VRINDA MANISH BUTTAN | G11: BT Top UP | H11: All that residential Flat/Apartment No. 701-B, admeasuring 88.72 Sq. Mtrs. (i.e. approximately 955.00 Sq. Feet), situated on the 7th Floor, in “D” Building of the project known as “Maestros”, constructed on land bearing Survey No. 60/7, situated at Village – Wanawadi (Wanorie), Taluka – Haveli, District – Pune, within the limits of Pune Municipal Corporation, together with undivided share of 0.190% in the land, along with all easements, rights and appurtenances thereto. | I11: 99
A12: =A11+1 -> 11 | B12: Adv. Narayan | C12: 77000251190_3 | D12: Baner | E12: VRINDA MANISH BUTTAN | G12: BT Top UP | H12: All that residential Flat/Apartment No. 801, admeasuring 88.26 Sq. Mtrs. (i.e. approximately 949.91 Sq. Feet), situated on the 8th Floor, in “D” Building of the project known as “Maestros”, constructed on land bearing Survey No. 60/7, situated at Village – Wanawadi (Wanorie), Taluka – Haveli, District – Pune, within the limits of Pune Municipal Corporation, together with adjoining terrace and terrace appurtenant to the said flat admeasuring in aggregate 157.93 Sq. Mtrs., along with undivided share of 0.190% in the land, together with all easements, rights and appurtenances thereto. | I12: 99
A13: =A12+1 -> 12 | B13: Adv. Narayan | C13: 7792150927 | D13: Hadapsar | E13: Bharat Motkar | G13: Resale | H13: All that piece and parcel of property admeasuring of H. 00-01.39 Ares, i.e. 139.40 sq. mtrs., i.e. 1500 sq. feets., out of land bearing Survey No. 39/2/3, having an area admeasuring of H. 00-83 Ares, assessed at Rs. 05-25 Paise, situated at Village – Manjari Budruk, Taluka – Haveli, District – Pune | I13: 99
A14: =A13+1 -> 13 | B14: Adv. Narayan | C14: 77000228844 | D14: Chinchwad | E14: Dhananjay Kulkarni | G14: Resale Home Loan | H14: All that piece and parcel of residential Flat bearing No. 104, situated on the First Floor in Wing ‘O’ of the building known as “Hubtown Countrywoods”, constructed on a part of the land bearing Survey No. 45/1/1 and other Hissa Numbers, admeasuring in aggregate 17 Hectares 27.1686 Ares (i.e. 1,72,716.86 Sq. Mtrs.), out of which an area admeasuring 11,969.99 Sq. Mtrs. is earmarked for the said project and out of which the building is constructed on land admeasuring 1,293.63 Sq. Mtrs., situated at Village Kondhwa Budruk, Taluka Haveli, District Pune, within the limits of Pune Municipal Corporation, the said Flat admeasuring Carpet Area 64.01 Sq. Mtrs. along with additional saleable terrace area admeasuring 3.43 Sq. Mtrs., together with one stilt car parking space and all easements, rights and appurtenances attached thereto. | I14: 99
A15: =A14+1 -> 14 | B15: Adv. Narayan | C15: 7792138312 | D15: Wakad | E15: Shubham Tayade | G15: Resale | H15: All that piece and parcel of property bearing H. 00-00.50 Ares, i.e. 500 sq. feets., out of Survey No. 79/13/10, having an area admeasuring of H. 00-01.50 Ares, assessed at Rs. 00-05 Paise, situated at Village – Rahatani, Taluka – Haveli, District – Pune | I15: 99
A16: =A15+1 -> 15 | B16: Adv. Narayan | C16: 77000249866 | D16: Kolhapur | E16: Bharat Sanjay Vaidya | G16: Apana Ghar Self Construction | H16: All that piece and parcel of non-agricultural property admeasuring 47.46 Sq. Mtrs., together with a residential house constructed in the year 2011, built with brick and mud walls and having a cement sheet roof, admeasuring 330 Sq. Ft., constructed on the land bearing CTS No. 460, situated at Village – Chandur, Taluka – Hatkanangale, District – Kolhapur | I16: 99
A17: =A16+1 -> 16 | B17: Adv. Narayan | C17: 77000240410 | D17: Hadapsar | E17: Abhijeet Auto Components Pvt Ltd | F17: 1) Mr. Jitendrakumar Narayan Singh 2) Mr. Arunkumar Narayan Singh 3) Mr. Santoshkumar Narayan Singh | G17: BT + TOP-UP | H17: All that piece and parcel of property admeasuring of H. 00-05 Ares, out of Survey No. 35, Hissa No. 2/1, having an area admeasuring of H. 01-30.50 Ares, together with Pot-Kharab area admeasuring of H. 00-33 Ares, i.e. total area admeasuring of H. 01-63.50 Ares, assessed at Rs. 02-62 Paise, situated at Village – Uruli Devachi, Taluka – Haveli, District – Pune | I17: 99
A18: =A17+1 -> 17 | B18: Adv. Narayan | C18: 77000247265 | D18: Kolhapur | E18: Mr.Umravati Jakkappa Patil | F18: Umesh Jakkappa Patil | G18: HL Premium Seller BT | H18: All that piece and parcel of non-agricultural property bearing Plot No. 5, having an area admeasuring of 104.80 sq. mtrs., together with construction of RCC building having an area admeasuring of 1150 sq. feets., carved out of Gat No. 282, Hissa No. 26, having an area admeasuring of H. 00-19 Ares, assessed at Rs. 00-22 Paise, situated at Village – Gokul Shirgaon, Taluka – Karveer, District – Kolhapur | I18: 99
A19: =A18+1 -> 18 | B19: Adv. Narayan | C19: 77000240220 | D19: Kolhapur | E19: Subhash Shamrao Patil | F19: Suman Subhash Patil | G19: Apana Ghar Regular | H19: All that piece and parcel of non-agricultural property admeasuring of H. 00-02 Ares, i.e. 200 sq. mtrs., out of Survey No. 15, Hissa No. 3/1, having total area admeasuring of H. 00-32 Ares, assessed at Rs. 04-25 Paise, situated at Village – Kokrud, Taluka – Shirala, District – Sangli | I19: 99
A20: =A19+1 -> 19 | B20: Adv. Narayan | C20: 77000254383 | D20: Kolhapur | E20: Tajmohammad | F20: Khairul Nesha | G20: Apana Ghar Regular | H20: All that piece and parcel of property admeasuring of Gat No. 298/1A/Plot No./37, having an area admeasuring of 66 sq. mtrs., together with RCC building consisting of Ground Floor having built-up area admeasuring of 52.80 sq. mtrs., and First Floor having built-up area admeasuring of 52.80 sq. mtrs., i.e. total built-up area admeasuring of 105.60 sq. mtrs., situated at Village – Kalambe Tarfe Thane, Taluka – Karveer, District – Kolhapur | I20: .
A21: =A20+1 -> 20 | B21: Adv. Narayan | C21: 77000225313 | D21: Kolhapur | E21: Tanaji Rau Vithekar | G21: Apana Ghar Regular (HL Self Construction) | H21: All that piece and parcel of the non-agricultural property bearing CTS No. 65, admeasuring 174.09 Sq. Mtrs., together with an existing structure constructed of stone, brick and mud, having a built-up area admeasuring 52.12 Sq. Mtrs., situated at Village Akurde, Taluka Panhala, District Kolhapur
A22: =A21+1 -> 21 | B22: Adv. Narayan | C22: 77000251375 | D22: Kolhapur | E22: Jagdish Mohanram Mahariya | F22: Dhannaram Mohanram Maharia | G22: LAP | H22: All that piece and parcel of property admeasuring of H. 00-14 Ares, out of Gat No. 54, having an area admeasuring of H. 00-85 Ares, together with Pot-Kharab area admeasuring of H. 00-09 Ares, assessed at Rs. 01-75 Paise, situated at Village – Vikaswadi, Taluka – Karveer, District – Kolhapur
A23: =A22+1 -> 22 | B23: Adv. Narayan | C23: 7800236434 | D23: Wakad | E23: Kanisfatima Imran Shaikh | F23: Imran Anwar Shaikh | G23: Resale | H23: All that piece and parcel of the property being Flat No. 122, admeasuring 693 Sq. Ft. i.e. 64.38 Sq. Mtrs. saleable area, situated on the Sixth Floor, in Wing “A” of the building known as “Waghere Towers”, constructed on the land bearing Survey No. 101/1B, CTS No. 6449 (part), situated at Village Pimpri Waghere, within the limits of Pimpri Chinchwad Municipal Corporation, Taluka Haveli, District Pune, together with all rights, easements and appurtenances thereto. | I23: 8888725508
A24: =A23+1 -> 23 | B24: Adv. Narayan | C24: 77000251172 | D24: Vishrantwadi | E24: Seema Abhijeet Rithe | F24: Nilesh Soundade | G24: Resale | H24: All that piece and parcel of the property being Flat No. 351, admeasuring 928 Sq. Ft. i.e. 86.25 Sq. Mtrs. carpet area, along with terrace admeasuring 109 Sq. Ft. i.e. 10.13 Sq. Mtrs., situated on the Third Floor, in Building No. “I” (Tropica I Co-operative Housing Society Limited) of the project known as “Tropica”, constructed on land bearing Survey Nos. 56/1A, 57/2, 58/1A and 57/1B, situated at Village Ravet, Taluka Haveli, District Pune, within the limits of Pimpri Chinchwad Municipal Corporation, together with Car Parking No. 727 (below central podium garden), bearing Property No. 1150103129.00 and Electricity Consumer No. 170074482328, along with all rights, easements and appurtenances thereto.
A25: =A24+1 -> 24 | B25: Adv. Narayan | C25: 77000254880 | E25: Anand Masurkar | G25: Builder Purchase
A26: =A25+1 -> 25 | B26: Adv. Narayan | C26: 77000249626 | D26: Kharadi | E26: Amit Arvind Kadam | F26: Pallavi Amit Kadam | G26: Balance Transfer | H26: All that piece and parcel of the property being Apartment No. 1304, admeasuring 53.52 Sq. Mtrs. carpet area, along with adjoining open balcony admeasuring 7.68 Sq. Mtrs., situated on the Thirteenth Floor, in Building No. “B” of the project known as “Yashada Supreme”, constructed on land bearing Gat No. 96 admeasuring 2 H 25 R (including Pot Kharaba area 0 H 3 R) and Gat No. 97 admeasuring 0 H 64 R (including Pot Kharaba area 0 H 1 R), aggregating to total land admeasuring 2 H 30 R, situated at Village Dudulgaon, Taluka Haveli, District Pune, within the limits of Pimpri Chinchwad Municipal Corporation, together with all rights, easements and appurtenances thereto.
A27: =A26+1 -> 26 | B27: Adv. Narayan | C27: 77000255326 | D27: Kolhapur | E27: Santosh Hirappa Sutar | F27: Suraj Hirappa Sutar | G27: Non Home Loan LAP | H27: All that piece and parcel of properties bearing- a. Plot No. 1, having an area admeasuring of 147.98 sq. mtrs., b. Plot No. 2, having an area admeasuring of 141.47 sq. mtrs., c. Plot No. 3, having an area admeasuring of 150.67 sq. mtrs., d. Plot No. 4, having an area admeasuring of 159.88 sq. mtrs., i.e. total area admeasuring of 600 sq. mtrs., carved out of entire land bearing R.S. No. 237/3/A, having total area admeasuring of H. 00-17.95 Ares, assessed at Rs. 02-10 Paise, situated at Village – Gokul Shirgaon, Taluka – Karveer, District – Kolhapur
A28: =A27+1 -> 27 | B28: Adv. Narayan | C28: 7792147873 | D28: Baner | E28: Mahika Sales and Services Private Limited | F28: Mr. Mahendrakumar Pandit Patil Mrs. Kavita Mahendrakumar Patil | G28: Plot Purchase | H28: All that piece and parcel of the plot being Plot No. D–13, admeasuring 86.40 Sq. Mtrs., together with proportionate (pro-rata) built-up area admeasuring 49.784 Sq. Mtrs., aggregating to total area admeasuring 136.184 Sq. Mtrs., having total permissible built-up area admeasuring 144.82 Sq. Mtrs., being part of the sanctioned layout known as “Sai Kuber Jewel”, as per Layout Plan bearing No. BP/Layout/Dudulgaon/37/2024 dated 12.07.2024 sanctioned by Pimpri Chinchwad Municipal Corporation, constructed on the land bearing Survey No. 216/1A, admeasuring 3789 Sq. Mtrs., situated at Village Dudulgaon, within the limits of Pimpri Chinchwad Municipal Corporation, Taluka Haveli, District Pune, together with all rights, easements and appurtenances thereto | I28: .
A29: =A28+1 -> 28 | B29: Adv. Narayan | C29: 7792145952 | D29: Wakad | E29: Amar Keshav Khote | F29: Shubhangi Amar Khote | G29: Resale | H29: All that piece and parcel of the property being Apartment/Flat No. 311, admeasuring 37.77 Sq. Mtrs. carpet area, along with balcony admeasuring 4.59 Sq. Mtrs. and one covered car parking space, situated on the Second Residential Habitable Floor, in Building/Tower “D” of the project known as “Life Republic – Sector R-10 / Avenue-10 (Universe) Phase-4”, constructed on land bearing New Survey No. 86 (Old Survey No. 78/1 Part, 80, 81 Part and others), New Survey No. 74/B (Old Survey No. 74/2, 74/3, 74/9/2 and others) and out of Survey Nos. 124/1/1 (Part), 124/1/2 (Part), 124/2 (Part) and others, situated at Villages Jambe, Nere and Marunji, Taluka Mulshi, District Pune, together with all rights, easements and appurtenances thereto. | I29: .
A30: =A29+1 -> 29 | B30: Adv. Narayan | C30: 77000240495 | D30: Hadapsar | E30: Akash Kale | F30: Swati Kale | G30: Plot + Construction | H30: All that piece and parcel of property bearing Private Plot No. 40, having an area admeasuring of H. 00-00.98 Ares, i.e. 1058 sq. fees., out of the project known as Sai Balaji Greens carved out of land bearing Survey No. 7, Hissa No. 6/6, admeasuring of H. 00-21 Ares, assessed at Rs. 00-75 Ares, situated at Village – Manjari Budruk, Taluka – Haveli, District – Pune | I30: .
A31: =A30+1 -> 30 | B31: Adv. Narayan | C31: 77000256070 | D31: Baner | E31: Subrata Nitai Patra | F31: Nil | G31: LAP BT + TOP UP | H31: All that piece and parcel of the property being Residential Apartment No. 7, admeasuring 74.34 Sq. Mtrs. built-up area, situated on the Third Floor, in the building known as “Vitthal Rukhmini Apartment”, constructed on the land bearing City Survey No. 477-A, situated at Raviwar Peth (Gaothan), Pune, Taluka Haveli, District Pune, within the local limits of Pune Municipal Corporation, Pune together with 12.86% undivided share in the common areas and facilities and all other rights, easements and appurtenances thereto. | I31: .
A32: =A31+1 -> 31 | B32: Adv. Narayan | C32: 77000216379 | D32: Baner | E32: Eknath Govind Pardeshi | F32: Gayatri Eknath Pardeshi | G32: Resale | H32: All that piece and parcel of proeprty bearing Flat No. A-7, having an area admeasuring of 500 sq. feets, situated ont eh Stilt Floor, out of the society known as "Gokul Park Co-Operative Housing Society Limited", constructed on the land bearing Plot No. RH-91/2, G-Block, MIDC, situated at Village - Akurdi, Taluka - Haveli, District - Pune and within local limits of Pimpri Chinchwad Municipal Corporation, Pimpri and wihtin jurisdiction of MIDC, Pimpri. | I32: .
A33: =A32+1 -> 32 | B33: Adv. Narayan | C33: 77000252808 | D33: Baner | E33: Prem Wilfred alosias Paul Monis | F33: Zitha Pinto | G33: HL Resale | H33: All that piece and parcel of property bearing Flat No. B-404, having an area admeasuring of 55.28 sq. mtrs., i.e. 595 sq. feets., (Carpet), along with terrace area admeasuring of 4.18 sq. mtrs., i.e. 45 sq. feets., situated on the Fourth Floor, out of the project known as “Nital Residency”, constructed on the entire land property, i.e. Survey No. 35, Hissa No. 1, situated at Village – Narhe, Taluka – Haveli, District – Pune and within local limits of Pune Municipal Corporation, Pune. | I33: .
A34: =A33+1 -> 33 | B34: Deepali | C34: 77000251513 | D34: Chinchwad | E34: Mr. Omprakash Sharma | F34: Mrs. Kiran Devi, W/o. Omprakash Sharma | G34: Builder Purchase | H34: All that piece and parcel of the Flat No.301 admeasuring 25.35 Sq. Mtrs. (Carpet Area) along with Enclosed Balcony admeasuring 7.45 Sq. Mtrs. and Open Balcony admeasuring 2.80 Sq. Mtrs. on the Third Floor, in the said project known as "Lotus Residency", constructed on the Private Plot No. 11 and 12 carved out of Survey No. 13/1A/3/2, situated at Village – Mamrudi, Taluka – Haveli, District – Pune and within local limits of Pimpri Chinchwad Municipal Corporation, Pimpri. | I34: .
A35: =A34+1 -> 34 | B35: Deepali | C35: 77000251175_1 | D35: Main | E35: Aaiji Developers | F35: Jiwaram Magaji Choudhary Suresh Jiwaram Choudhary Hemant Jiwaram Choudhary | G35: Lap Commercial | H35: All that piece and parcel of property bearing Office No. 401, having carpet area admeasuring of 714.50 sq. mtrs., situated on the Fourth Floor, out of the project known as “Solitaire Business Hub – Baner”, constructed on the entire land bearing Survey No. 3/7B,+ 9 situated at Village Baner, Taluka – Haveli, District – Pune and within local limits of Pune Municipal Corporation, Pune.
A36: 34A | B36: Deepali | C36: 77000251175_2 | D36: Main | E36: Aaiji Developers | F36: Jiwaram Magaji Choudhary Suresh Jiwaram Choudhary Hemant Jiwaram Choudhary | G36: Lap Commercial | H36: All that piece and parcel of property bearing Office No. 501, having carpet area admeasuring of 714.50 sq. mtrs., situated on the Fifth Floor, out of the project known as “Solitaire Business Hub – Baner”, constructed on the entire land bearing Survey No. 3/7B,+ 9 situated at Village Baner, Taluka – Haveli, District – Pune and within local limits of Pune Municipal Corporation, Pune.
A37: =A35+1 -> 35 | B37: Deepali | C37: 77000258297 | D37: Kolhapur | E37: Anand Madhukar Patil | F37: Rupali Anand patil | G37: Regular HL BT+ TOP-UP | H37: All that piece and parcel of the property bearing Plot No. 64A out of Gut No. 546/1/B/64/A (formed under Gunthewari), admeasuring 204.46 Sq. Mtrs. i.e. 2200 Sq. Ft., situated at E Ward, Kasba Bawda, within the limits of Kolhapur Municipal Corporation, together with a structure thereon comprising a tin shed construction admeasuring 45.00 Sq. Mtrs. (built-up), along with all rights, easements and appurtenances attached thereto
A38: =A37+1 -> 36 | B38: Deepali | C38: 77000256309 | D38: Kolhapur | E38: Dipak Sambhaji Kadam | F38: Rahul Sambhaji Kadam Bharati Rahul Kadam | G38: Regular P+C | H38: A ward Karvir Kolhapur S.No.896
A39: =A38+1 -> 37 | B39: Deepali | C39: 77000255771 | D39: Kolhapur | E39: Satish Mahadev Vetale | F39: Radhika Satish Vetale | G39: BT + TOP-UP | H39: Kasababavda Kolhapur S.No.1476
A40: =A39+1 -> 38 | B40: Deepali | C40: 77000251849 | D40: Kolhapur | E40: Suhas Appasaheb Gavali | F40: Rajshri Suhas Gavali | G40: Regular Lap BT+Topup | H40: A ward Karvir Kolhapur S.No. 858
...

Sheet TSR Initiation
B1: Author | C1: Application ID | D1: Branch | E1: Initiation Date | F1: Applicant | G1: Co-Applicant | H1: Transaction Type | I1: Property Details | J1: Executive Mobile No | K1: Executive Email | L1: Status | M1: Remark
B2: Narayan | C2: 77000234182 | D2: {=XLOOKUP(C2,'Master Data'!C:C,'Master Data'!D:D)} -> Main | F2: {=XLOOKUP(C2,'Master Data'!C:C,'Master Data'!E:E)} -> Swapan Mandol | G2: {=XLOOKUP(C2,'Master Data'!C:C,'Master Data'!F:F)} -> ABC | H2: {=XLOOKUP(C2,'Master Data'!C:C,'Master Data'!G:G)} -> Resale | I2: {=XLOOKUP(C2,'Master Data'!C:C,'Master Data'!H:H)} -> Pune. Ganesh Peth. CTS No. 48 | J2: {=XLOOKUP(C2,'Master Data'!C:C,'Master Data'!I:I)} -> 99 | K2: {=XLOOKUP(C2,'Master Data'!C:C,'Master Data'!J:J)} | L2: {=XLOOKUP(C:C,TSR_Completion!C:C,TSR_Completion!M:M)} -> Completed and Issued
A3: 576 | B3: Narayan | C3: 77000240220 | D3: {=XLOOKUP(C3,'Master Data'!C:C,'Master Data'!D:D)} -> Kolhapur | E3: 04.04.2026 | F3: {=XLOOKUP(C3,'Master Data'!C:C,'Master Data'!E:E)} -> Subhash Shamrao Patil | G3: {=XLOOKUP(C3,'Master Data'!C:C,'Master Data'!F:F)} -> Suman Subhash Patil | H3: {=XLOOKUP(C3,'Master Data'!C:C,'Master Data'!G:G)} -> Apana Ghar Regular | I3: {=XLOOKUP(C3,'Master Data'!C:C,'Master Data'!H:H)} -> All that piece and parcel of non-agricultural property admeasuring of H. 00-02 Ares, i.e. 200 sq. mtrs., out of Survey No. 15, Hissa No. 3/1, having total area admeasuring of H. 00-32 Ares, assessed at Rs. 04-25 Paise, situated at Village – Kokrud, Taluka – Shirala, District – Sangli | J3: {=XLOOKUP(C3,'Master Data'!C:C,'Master Data'!I:I)} -> 99 | K3: {=XLOOKUP(C3,'Master Data'!C:C,'Master Data'!J:J)} | L3: {=XLOOKUP(C:C,TSR_Completion!C:C,TSR_Completion!M:M)} -> Completed and Issued | M3: Results Downloaded_Pooja
A4: 577 | B4: Narayan | C4: 77000254383 | D4: {=XLOOKUP(C4,'Master Data'!C:C,'Master Data'!D:D)} -> Kolhapur | E4: 06.04.2026 | F4: {=XLOOKUP(C4,'Master Data'!C:C,'Master Data'!E:E)} -> Tajmohammad | G4: {=XLOOKUP(C4,'Master Data'!C:C,'Master Data'!F:F)} -> Khairul Nesha | H4: {=XLOOKUP(C4,'Master Data'!C:C,'Master Data'!G:G)} -> Apana Ghar Regular | I4: {=XLOOKUP(C4,'Master Data'!C:C,'Master Data'!H:H)} -> All that piece and parcel of property admeasuring of Gat No. 298/1A/Plot No./37, having an area admeasuring of 66 sq. mtrs., together with RCC building consisting of Ground Floor having built-up area admeasuring of 52.80 sq. mtrs., and First Floor having built-up area admeasuring of 52.80 sq. mtrs., i.e. total built-up area admeasuring of 105.60 sq. mtrs., situated at Village – Kalambe Tarfe Thane, Taluka – Karveer, District – Kolhapur | J4: {=XLOOKUP(C4,'Master Data'!C:C,'Master Data'!I:I)} -> . | K4: {=XLOOKUP(C4,'Master Data'!C:C,'Master Data'!J:J)} | L4: {=XLOOKUP(C:C,TSR_Completion!C:C,TSR_Completion!M:M)} -> Completed and Issued | M4: Done by Deepali
A5: 578 | B5: Narayan | C5: 77000225313 | D5: {=XLOOKUP(C5,'Master Data'!C:C,'Master Data'!D:D)} -> Kolhapur | E5: 06.04.2026 | F5: {=XLOOKUP(C5,'Master Data'!C:C,'Master Data'!E:E)} -> Tanaji Rau Vithekar | G5: {=XLOOKUP(C5,'Master Data'!C:C,'Master Data'!F:F)} | H5: {=XLOOKUP(C5,'Master Data'!C:C,'Master Data'!G:G)} -> Apana Ghar Regular (HL Self Construction) | I5: {=XLOOKUP(C5,'Master Data'!C:C,'Master Data'!H:H)} -> All that piece and parcel of the non-agricultural property bearing CTS No. 65, admeasuring 174.09 Sq. Mtrs., together with an existing structure constructed of stone, brick and mud, having a built-up area admeasuring 52.12 Sq. Mtrs., situated at Village Akurde, Taluka Panhala, District Kolhapur | J5: {=XLOOKUP(C5,'Master Data'!C:C,'Master Data'!I:I)} | K5: {=XLOOKUP(C5,'Master Data'!C:C,'Master Data'!J:J)} | L5: {=XLOOKUP(C:C,TSR_Completion!C:C,TSR_Completion!M:M)} -> Completed and Issued | M5: Done by Deepali
A6: 580 | B6: Narayan | C6: 77000251375 | D6: {=XLOOKUP(C6,'Master Data'!C:C,'Master Data'!D:D)} -> Kolhapur | E6: 07.04.2026 | F6: {=XLOOKUP(C6,'Master Data'!C:C,'Master Data'!E:E)} -> Jagdish Mohanram Mahariya | G6: {=XLOOKUP(C6,'Master Data'!C:C,'Master Data'!F:F)} -> Dhannaram Mohanram Maharia | H6: {=XLOOKUP(C6,'Master Data'!C:C,'Master Data'!G:G)} -> LAP | I6: {=XLOOKUP(C6,'Master Data'!C:C,'Master Data'!H:H)} -> All that piece and parcel of property admeasuring of H. 00-14 Ares, out of Gat No. 54, having an area admeasuring of H. 00-85 Ares, together with Pot-Kharab area admeasuring of H. 00-09 Ares, assessed at Rs. 01-75 Paise, situated at Village – Vikaswadi, Taluka – Karveer, District – Kolhapur | J6: {=XLOOKUP(C6,'Master Data'!C:C,'Master Data'!I:I)} | K6: {=XLOOKUP(C6,'Master Data'!C:C,'Master Data'!J:J)} | L6: {=XLOOKUP(C:C,TSR_Completion!C:C,TSR_Completion!M:M)} -> Completed and Issued | M6: Results Downloaded_Pooja
A7: 582 | B7: Narayan | C7: 7800236434 | D7: {=XLOOKUP(C7,'Master Data'!C:C,'Master Data'!D:D)} -> Wakad | E7: 07.04.2026 | F7: {=XLOOKUP(C7,'Master Data'!C:C,'Master Data'!E:E)} -> Kanisfatima Imran Shaikh | G7: {=XLOOKUP(C7,'Master Data'!C:C,'Master Data'!F:F)} -> Imran Anwar Shaikh | H7: {=XLOOKUP(C7,'Master Data'!C:C,'Master Data'!G:G)} -> Resale | I7: {=XLOOKUP(C7,'Master Data'!C:C,'Master Data'!H:H)} -> All that piece and parcel of the property being Flat No. 122, admeasuring 693 Sq. Ft. i.e. 64.38 Sq. Mtrs. saleable area, situated on the Sixth Floor, in Wing “A” of the building known as “Waghere Towers”, constructed on the land bearing Survey No. 101/1B, CTS No. 6449 (part), situated at Village Pimpri Waghere, within the limits of Pimpri Chinchwad Municipal Corporation, Taluka Haveli, District Pune, together with all rights, easements and appurtenances thereto. | J7: {=XLOOKUP(C7,'Master Data'!C:C,'Master Data'!I:I)} -> 8888725508 | K7: {=XLOOKUP(C7,'Master Data'!C:C,'Master Data'!J:J)} | L7: {=XLOOKUP(C:C,TSR_Completion!C:C,TSR_Completion!M:M)} -> Completed and Issued | M7: Results Downloaded_Pooja
A8: 583 | B8: Narayan | C8: 77000251172 | D8: {=XLOOKUP(C8,'Master Data'!C:C,'Master Data'!D:D)} -> Vishrantwadi | E8: 15.04.2026 | F8: {=XLOOKUP(C8,'Master Data'!C:C,'Master Data'!E:E)} -> Seema Abhijeet Rithe | G8: {=XLOOKUP(C8,'Master Data'!C:C,'Master Data'!F:F)} -> Nilesh Soundade | H8: {=XLOOKUP(C8,'Master Data'!C:C,'Master Data'!G:G)} -> Resale | I8: {=XLOOKUP(C8,'Master Data'!C:C,'Master Data'!H:H)} -> All that piece and parcel of the property being Flat No. 351, admeasuring 928 Sq. Ft. i.e. 86.25 Sq. Mtrs. carpet area, along with terrace admeasuring 109 Sq. Ft. i.e. 10.13 Sq. Mtrs., situated on the Third Floor, in Building No. “I” (Tropica I Co-operative Housing Society Limited) of the project known as “Tropica”, constructed on land bearing Survey Nos. 56/1A, 57/2, 58/1A and 57/1B, situated at Village Ravet, Taluka Haveli, District Pune, within the limits of Pimpri Chinchwad Municipal Corporation, together with Car Parking No. 727 (below central podium garden), bearing Property No. 1150103129.00 and Electricity Consumer No. 170074482328, along with all rights, easements and appurtenances thereto. | J8: {=XLOOKUP(C8,'Master Data'!C:C,'Master Data'!I:I)} | K8: {=XLOOKUP(C8,'Master Data'!C:C,'Master Data'!J:J)} | L8: {=XLOOKUP(C:C,TSR_Completion!C:C,TSR_Completion!M:M)} -> Completed and Issued | M8: Results Downloaded_Pooja
B9: Narayan | C9: 77000254880 | D9: {=XLOOKUP(C9,'Master Data'!C:C,'Master Data'!D:D)} | F9: {=XLOOKUP(C9,'Master Data'!C:C,'Master Data'!E:E)} -> Anand Masurkar | G9: {=XLOOKUP(C9,'Master Data'!C:C,'Master Data'!F:F)} | H9: {=XLOOKUP(C9,'Master Data'!C:C,'Master Data'!G:G)} -> Builder Purchase | I9: {=XLOOKUP(C9,'Master Data'!C:C,'Master Data'!H:H)} | J9: {=XLOOKUP(C9,'Master Data'!C:C,'Master Data'!I:I)} | K9: {=XLOOKUP(C9,'Master Data'!C:C,'Master Data'!J:J)} | L9: {=XLOOKUP(C:C,TSR_Completion!C:C,TSR_Completion!M:M)} -> #N/A
A10: 584 | B10: Narayan | C10: 77000249626 | D10: {=XLOOKUP(C10,'Master Data'!C:C,'Master Data'!D:D)} -> Kharadi | E10: 08.04.2026 | F10: {=XLOOKUP(C10,'Master Data'!C:C,'Master Data'!E:E)} -> Amit Arvind Kadam | G10: {=XLOOKUP(C10,'Master Data'!C:C,'Master Data'!F:F)} -> Pallavi Amit Kadam | H10: {=XLOOKUP(C10,'Master Data'!C:C,'Master Data'!G:G)} -> Balance Transfer | I10: {=XLOOKUP(C10,'Master Data'!C:C,'Master Data'!H:H)} -> All that piece and parcel of the property being Apartment No. 1304, admeasuring 53.52 Sq. Mtrs. carpet area, along with adjoining open balcony admeasuring 7.68 Sq. Mtrs., situated on the Thirteenth Floor, in Building No. “B” of the project known as “Yashada Supreme”, constructed on land bearing Gat No. 96 admeasuring 2 H 25 R (including Pot Kharaba area 0 H 3 R) and Gat No. 97 admeasuring 0 H 64 R (including Pot Kharaba area 0 H 1 R), aggregating to total land admeasuring 2 H 30 R, situated at Village Dudulgaon, Taluka Haveli, District Pune, within the limits of Pimpri Chinchwad Municipal Corporation, together with all rights, easements and appurtenances thereto. | J10: {=XLOOKUP(C10,'Master Data'!C:C,'Master Data'!I:I)} | K10: {=XLOOKUP(C10,'Master Data'!C:C,'Master Data'!J:J)} | L10: {=XLOOKUP(C:C,TSR_Completion!C:C,TSR_Completion!M:M)} -> Completed and Issued | M10: Results Downloaded_Pooja
A11: 599 | B11: Narayan | C11: 77000255326 | D11: {=XLOOKUP(C11,'Master Data'!C:C,'Master Data'!D:D)} -> Kolhapur | E11: 09.04.2026 | F11: {=XLOOKUP(C11,'Master Data'!C:C,'Master Data'!E:E)} -> Santosh Hirappa Sutar | G11: {=XLOOKUP(C11,'Master Data'!C:C,'Master Data'!F:F)} -> Suraj Hirappa Sutar | H11: {=XLOOKUP(C11,'Master Data'!C:C,'Master Data'!G:G)} -> Non Home Loan LAP | I11: {=XLOOKUP(C11,'Master Data'!C:C,'Master Data'!H:H)} -> All that piece and parcel of properties bearing- a. Plot No. 1, having an area admeasuring of 147.98 sq. mtrs., b. Plot No. 2, having an area admeasuring of 141.47 sq. mtrs., c. Plot No. 3, having an area admeasuring of 150.67 sq. mtrs., d. Plot No. 4, having an area admeasuring of 159.88 sq. mtrs., i.e. total area admeasuring of 600 sq. mtrs., carved out of entire land bearing R.S. No. 237/3/A, having total area admeasuring of H. 00-17.95 Ares, assessed at Rs. 02-10 Paise, situated at Village – Gokul Shirgaon, Taluka – Karveer, District – Kolhapur | J11: {=XLOOKUP(C11,'Master Data'!C:C,'Master Data'!I:I)} | K11: {=XLOOKUP(C11,'Master Data'!C:C,'Master Data'!J:J)} | L11: {=XLOOKUP(C:C,TSR_Completion!C:C,TSR_Completion!M:M)} -> Completed and Issued | M11: Results Downloaded_Pooja
A12: 581 | B12: Narayan | C12: 7792147873 | D12: {=XLOOKUP(C12,'Master Data'!C:C,'Master Data'!D:D)} -> Baner | E12: 09.04.2026 | F12: {=XLOOKUP(C12,'Master Data'!C:C,'Master Data'!E:E)} -> Mahika Sales and Services Private Limited | G12: {=XLOOKUP(C12,'Master Data'!C:C,'Master Data'!F:F)} -> Mr. Mahendrakumar Pandit Patil Mrs. Kavita Mahendrakumar Patil | H12: {=XLOOKUP(C12,'Master Data'!C:C,'Master Data'!G:G)} -> Plot Purchase | I12: {=XLOOKUP(C12,'Master Data'!C:C,'Master Data'!H:H)} -> All that piece and parcel of the plot being Plot No. D–13, admeasuring 86.40 Sq. Mtrs., together with proportionate (pro-rata) built-up area admeasuring 49.784 Sq. Mtrs., aggregating to total area admeasuring 136.184 Sq. Mtrs., having total permissible built-up area admeasuring 144.82 Sq. Mtrs., being part of the sanctioned layout known as “Sai Kuber Jewel”, as per Layout Plan bearing No. BP/Layout/Dudulgaon/37/2024 dated 12.07.2024 sanctioned by Pimpri Chinchwad Municipal Corporation, constructed on the land bearing Survey No. 216/1A, admeasuring 3789 Sq. Mtrs., situated at Village Dudulgaon, within the limits of Pimpri Chinchwad Municipal Corporation, Taluka Haveli, District Pune, together with all rights, easements and appurtenances thereto | J12: {=XLOOKUP(C12,'Master Data'!C:C,'Master Data'!I:I)} -> . | K12: {=XLOOKUP(C12,'Master Data'!C:C,'Master Data'!J:J)} | L12: {=XLOOKUP(C:C,TSR_Completion!C:C,TSR_Completion!M:M)} -> Completed and Issued
A13: 585 | B13: Narayan | C13: 7792145952 | D13: {=XLOOKUP(C13,'Master Data'!C:C,'Master Data'!D:D)} -> Wakad | E13: 09.04.2026 | F13: {=XLOOKUP(C13,'Master Data'!C:C,'Master Data'!E:E)} -> Amar Keshav Khote | G13: {=XLOOKUP(C13,'Master Data'!C:C,'Master Data'!F:F)} -> Shubhangi Amar Khote | H13: Resale | I13: {=XLOOKUP(C13,'Master Data'!C:C,'Master Data'!H:H)} -> All that piece and parcel of the property being Apartment/Flat No. 311, admeasuring 37.77 Sq. Mtrs. carpet area, along with balcony admeasuring 4.59 Sq. Mtrs. and one covered car parking space, situated on the Second Residential Habitable Floor, in Building/Tower “D” of the project known as “Life Republic – Sector R-10 / Avenue-10 (Universe) Phase-4”, constructed on land bearing New Survey No. 86 (Old Survey No. 78/1 Part, 80, 81 Part and others), New Survey No. 74/B (Old Survey No. 74/2, 74/3, 74/9/2 and others) and out of Survey Nos. 124/1/1 (Part), 124/1/2 (Part), 124/2 (Part) and others, situated at Villages Jambe, Nere and Marunji, Taluka Mulshi, District Pune, together with all rights, easements and appurtenances thereto. | J13: {=XLOOKUP(C13,'Master Data'!C:C,'Master Data'!I:I)} -> . | K13: {=XLOOKUP(C13,'Master Data'!C:C,'Master Data'!J:J)} | L13: {=XLOOKUP(C:C,TSR_Completion!C:C,TSR_Completion!M:M)} -> Completed and Issued | M13: Done by Deepali
A14: 587 | B14: Narayan | C14: 77000251513 | D14: {=XLOOKUP(C14,'Master Data'!C:C,'Master Data'!D:D)} -> Chinchwad | E14: 10.04.2026 | F14: {=XLOOKUP(C14,'Master Data'!C:C,'Master Data'!E:E)} -> Mr. Omprakash Sharma | G14: {=XLOOKUP(C14,'Master Data'!C:C,'Master Data'!F:F)} -> Mrs. Kiran Devi, W/o. Omprakash Sharma | H14: {=XLOOKUP(C14,'Master Data'!C:C,'Master Data'!G:G)} -> Builder Purchase | I14: {=XLOOKUP(C14,'Master Data'!C:C,'Master Data'!H:H)} -> All that piece and parcel of the Flat No.301 admeasuring 25.35 Sq. Mtrs. (Carpet Area) along with Enclosed Balcony admeasuring 7.45 Sq. Mtrs. and Open Balcony admeasuring 2.80 Sq. Mtrs. on the Third Floor, in the said project known as "Lotus Residency", constructed on the Private Plot No. 11 and 12 carved out of Survey No. 13/1A/3/2, situated at Village – Mamrudi, Taluka – Haveli, District – Pune and within local limits of Pimpri Chinchwad Municipal Corporation, Pimpri. | J14: {=XLOOKUP(C14,'Master Data'!C:C,'Master Data'!I:I)} -> . | K14: {=XLOOKUP(C14,'Master Data'!C:C,'Master Data'!J:J)} | L14: {=XLOOKUP(C:C,TSR_Completion!C:C,TSR_Completion!M:M)} -> Completed and Issued | M14: Done by Deepali
A15: 574 | B15: Narayan | C15: 77000240495 | D15: {=XLOOKUP(C15,'Master Data'!C:C,'Master Data'!D:D)} -> Hadapsar | E15: 02.04.2026 | F15: Akash Dnyanoba Kale | G15: Swati Akash Kale | H15: {=XLOOKUP(C15,'Master Data'!C:C,'Master Data'!G:G)} -> Plot + Construction | I15: {=XLOOKUP(C15,'Master Data'!C:C,'Master Data'!H:H)} -> All that piece and parcel of property bearing Private Plot No. 40, having an area admeasuring of H. 00-00.98 Ares, i.e. 1058 sq. fees., out of the project known as Sai Balaji Greens carved out of land bearing Survey No. 7, Hissa No. 6/6, admeasuring of H. 00-21 Ares, assessed at Rs. 00-75 Ares, situated at Village – Manjari Budruk, Taluka – Haveli, District – Pune | J15: {=XLOOKUP(C15,'Master Data'!C:C,'Master Data'!I:I)} -> . | K15: {=XLOOKUP(C15,'Master Data'!C:C,'Master Data'!J:J)} | L15: {=XLOOKUP(C:C,TSR_Completion!C:C,TSR_Completion!M:M)} -> Completed and Issued | M15: Results Downloaded_Pooja
A16: =A15+1 -> 575 | B16: Narayan | C16: 77000247265 | D16: {=XLOOKUP(C16,'Master Data'!C:C,'Master Data'!D:D)} -> Kolhapur | E16: 28.03.2026 | F16: {=XLOOKUP(C16,'Master Data'!C:C,'Master Data'!E:E)} -> Mr.Umravati Jakkappa Patil | G16: {=XLOOKUP(C16,'Master Data'!C:C,'Master Data'!F:F)} -> Umesh Jakkappa Patil | H16: {=XLOOKUP(C16,'Master Data'!C:C,'Master Data'!G:G)} -> HL Premium Seller BT | I16: {=XLOOKUP(C16,'Master Data'!C:C,'Master Data'!H:H)} -> All that piece and parcel of non-agricultural property bearing Plot No. 5, having an area admeasuring of 104.80 sq. mtrs., together with construction of RCC building having an area admeasuring of 1150 sq. feets., carved out of Gat No. 282, Hissa No. 26, having an area admeasuring of H. 00-19 Ares, assessed at Rs. 00-22 Paise, situated at Village – Gokul Shirgaon, Taluka – Karveer, District – Kolhapur | J16: {=XLOOKUP(C16,'Master Data'!C:C,'Master Data'!I:I)} -> 99 | K16: {=XLOOKUP(C16,'Master Data'!C:C,'Master Data'!J:J)} | L16: {=XLOOKUP(C:C,TSR_Completion!C:C,TSR_Completion!M:M)} -> Completed and Issued | M16: Results Downloaded_Pooja
A17: 579 | B17: Narayan | C17: 77000256070 | D17: {=XLOOKUP(C17,'Master Data'!C:C,'Master Data'!D:D)} -> Baner | E17: 04.04.2026 | F17: {=XLOOKUP(C17,'Master Data'!C:C,'Master Data'!E:E)} -> Subrata Nitai Patra | G17: {=XLOOKUP(C17,'Master Data'!C:C,'Master Data'!F:F)} -> Nil | H17: {=XLOOKUP(C17,'Master Data'!C:C,'Master Data'!G:G)} -> LAP BT + TOP UP | I17: {=XLOOKUP(C17,'Master Data'!C:C,'Master Data'!H:H)} -> All that piece and parcel of the property being Residential Apartment No. 7, admeasuring 74.34 Sq. Mtrs. built-up area, situated on the Third Floor, in the building known as “Vitthal Rukhmini Apartment”, constructed on the land bearing City Survey No. 477-A, situated at Raviwar Peth (Gaothan), Pune, Taluka Haveli, District Pune, within the local limits of Pune Municipal Corporation, Pune together with 12.86% undivided share in the common areas and facilities and all other rights, easements and appurtenances thereto. | J17: {=XLOOKUP(C17,'Master Data'!C:C,'Master Data'!I:I)} -> . | K17: {=XLOOKUP(C17,'Master Data'!C:C,'Master Data'!J:J)} | L17: {=XLOOKUP(C:C,TSR_Completion!C:C,TSR_Completion!M:M)} -> Completed and Issued | M17: Results Downloaded_Pooja
A18: 586 | B18: Narayan | C18: 77000252808 | D18: {=XLOOKUP(C18,'Master Data'!C:C,'Master Data'!D:D)} -> Baner | E18: 07.04.2026 | F18: {=XLOOKUP(C18,'Master Data'!C:C,'Master Data'!E:E)} -> Prem Wilfred alosias Paul Monis | G18: {=XLOOKUP(C18,'Master Data'!C:C,'Master Data'!F:F)} -> Zitha Pinto | H18: {=XLOOKUP(C18,'Master Data'!C:C,'Master Data'!G:G)} -> HL Resale | I18: {=XLOOKUP(C18,'Master Data'!C:C,'Master Data'!H:H)} -> All that piece and parcel of property bearing Flat No. B-404, having an area admeasuring of 55.28 sq. mtrs., i.e. 595 sq. feets., (Carpet), along with terrace area admeasuring of 4.18 sq. mtrs., i.e. 45 sq. feets., situated on the Fourth Floor, out of the project known as “Nital Residency”, constructed on the entire land property, i.e. Survey No. 35, Hissa No. 1, situated at Village – Narhe, Taluka – Haveli, District – Pune and within local limits of Pune Municipal Corporation, Pune. | J18: {=XLOOKUP(C18,'Master Data'!C:C,'Master Data'!I:I)} -> . | K18: {=XLOOKUP(C18,'Master Data'!C:C,'Master Data'!J:J)} | L18: {=XLOOKUP(C:C,TSR_Completion!C:C,TSR_Completion!M:M)} -> Completed and Issued | M18: Results Downloaded_Pooja
A19: 600 | B19: Narayan | C19: 77000258297 | D19: {=XLOOKUP(C19,'Master Data'!C:C,'Master Data'!D:D)} -> Kolhapur | E19: 13.04.2026 | F19: {=XLOOKUP(C19,'Master Data'!C:C,'Master Data'!E:E)} -> Anand Madhukar Patil | G19: {=XLOOKUP(C19,'Master Data'!C:C,'Master Data'!F:F)} -> Rupali Anand patil | H19: {=XLOOKUP(C19,'Master Data'!C:C,'Master Data'!G:G)} -> Regular HL BT+ TOP-UP | I19: {=XLOOKUP(C19,'Master Data'!C:C,'Master Data'!H:H)} -> All that piece and parcel of the property bearing Plot No. 64A out of Gut No. 546/1/B/64/A (formed under Gunthewari), admeasuring 204.46 Sq. Mtrs. i.e. 2200 Sq. Ft., situated at E Ward, Kasba Bawda, within the limits of Kolhapur Municipal Corporation, together with a structure thereon comprising a tin shed construction admeasuring 45.00 Sq. Mtrs. (built-up), along with all rights, easements and appurtenances attached thereto | J19: {=XLOOKUP(C19,'Master Data'!C:C,'Master Data'!I:I)} | K19: {=XLOOKUP(C19,'Master Data'!C:C,'Master Data'!J:J)} | L19: {=XLOOKUP(C:C,TSR_Completion!C:C,TSR_Completion!M:M)} -> Completed and Issued | M19: Results Downloaded_Pooja
A20: 601 | B20: Narayan | C20: 77000256309 | D20: {=XLOOKUP(C20,'Master Data'!C:C,'Master Data'!D:D)} -> Kolhapur | E20: 13.04.2026 | F20: {=XLOOKUP(C20,'Master Data'!C:C,'Master Data'!E:E)} -> Dipak Sambhaji Kadam | G20: {=XLOOKUP(C20,'Master Data'!C:C,'Master Data'!F:F)} -> Rahul Sambhaji Kadam Bharati Rahul Kadam | H20: {=XLOOKUP(C20,'Master Data'!C:C,'Master Data'!G:G)} -> Regular P+C | I20: {=XLOOKUP(C20,'Master Data'!C:C,'Master Data'!H:H)} -> A ward Karvir Kolhapur S.No.896 | J20: {=XLOOKUP(C20,'Master Data'!C:C,'Master Data'!I:I)} | K20: {=XLOOKUP(C20,'Master Data'!C:C,'Master Data'!J:J)} | L20: {=XLOOKUP(C:C,TSR_Completion!C:C,TSR_Completion!M:M)} -> Completed and Issued | M20: Results Downloaded_Pooja
A21: 603 | B21: Narayan | C21: 77000255771 | D21: {=XLOOKUP(C21,'Master Data'!C:C,'Master Data'!D:D)} -> Kolhapur | E21: 13.04.2026 | F21: {=XLOOKUP(C21,'Master Data'!C:C,'Master Data'!E:E)} -> Satish Mahadev Vetale | G21: {=XLOOKUP(C21,'Master Data'!C:C,'Master Data'!F:F)} -> Radhika Satish Vetale | H21: {=XLOOKUP(C21,'Master Data'!C:C,'Master Data'!G:G)} -> BT + TOP-UP | I21: {=XLOOKUP(C21,'Master Data'!C:C,'Master Data'!H:H)} -> Kasababavda Kolhapur S.No.1476 | J21: {=XLOOKUP(C21,'Master Data'!C:C,'Master Data'!I:I)} | K21: {=XLOOKUP(C21,'Master Data'!C:C,'Master Data'!J:J)} | L21: {=XLOOKUP(C:C,TSR_Completion!C:C,TSR_Completion!M:M)} -> Completed and Issued | M21: Results Downloaded_Pooja
A22: 602 | B22: Narayan | C22: 77000251849 | D22: {=XLOOKUP(C22,'Master Data'!C:C,'Master Data'!D:D)} -> Kolhapur | E22: 13.04.2026 | F22: {=XLOOKUP(C22,'Master Data'!C:C,'Master Data'!E:E)} -> Suhas Appasaheb Gavali | G22: {=XLOOKUP(C22,'Master Data'!C:C,'Master Data'!F:F)} -> Rajshri Suhas Gavali | H22: {=XLOOKUP(C22,'Master Data'!C:C,'Master Data'!G:G)} -> Regular Lap BT+Topup | I22: {=XLOOKUP(C22,'Master Data'!C:C,'Master Data'!H:H)} -> A ward Karvir Kolhapur S.No. 858 | J22: {=XLOOKUP(C22,'Master Data'!C:C,'Master Data'!I:I)} | K22: {=XLOOKUP(C22,'Master Data'!C:C,'Master Data'!J:J)} | L22: {=XLOOKUP(C:C,TSR_Completion!C:C,TSR_Completion!M:M)} -> Completed and Issued | M22: Results Downloaded_Pooja
A23: 588 | B23: Narayan | C23: 7792148754 | D23: {=XLOOKUP(C23,'Master Data'!C:C,'Master Data'!D:D)} -> Chinchwad | E23: 10.04.2026 | F23: {=XLOOKUP(C23,'Master Data'!C:C,'Master Data'!E:E)} -> Vijendrasingh m tak | G23: {=XLOOKUP(C23,'Master Data'!C:C,'Master Data'!F:F)} | H23: {=XLOOKUP(C23,'Master Data'!C:C,'Master Data'!G:G)} -> LAP | I23: {=XLOOKUP(C23,'Master Data'!C:C,'Master Data'!H:H)} -> Lohagaon S.No.71 | J23: {=XLOOKUP(C23,'Master Data'!C:C,'Master Data'!I:I)} | K23: {=XLOOKUP(C23,'Master Data'!C:C,'Master Data'!J:J)} | L23: {=XLOOKUP(C:C,TSR_Completion!C:C,TSR_Completion!M:M)} -> #N/A | M23: Done by Deepali Copy of Gift Deed and 7/12 pending.
A24: 589 | B24: Narayan | C24: 7792151842 | D24: {=XLOOKUP(C24,'Master Data'!C:C,'Master Data'!D:D)} -> Wakad | E24: 13.04.2026 | F24: {=XLOOKUP(C24,'Master Data'!C:C,'Master Data'!E:E)} -> Prabhakar Nagesh Tandale | G24: {=XLOOKUP(C24,'Master Data'!C:C,'Master Data'!F:F)} -> Aruna Prabhakar Tandale | H24: {=XLOOKUP(C24,'Master Data'!C:C,'Master Data'!G:G)} -> Builder Purchase Non APF | I24: {=XLOOKUP(C24,'Master Data'!C:C,'Master Data'!H:H)} -> All that piece and parcel of the Flat No. 403, admeasuring Carpet Area 37.44 Sq. Mtrs. along with Sit-out Area 3.57 Sq. Mtrs., situated on the Fourth Floor, in Building “D” (EWS) of the project known as “Gangadham Towers”, constructed on the land bearing CTS No. 370, Hissa No. 4 (earlier Survey No. 578, Hissa No. 2), situated at Village Bibwewadi (Munjeri), Taluka Pune City, District Pune, within the limits of Pune Municipal Corporation. | J24: {=XLOOKUP(C24,'Master Data'!C:C,'Master Data'!I:I)} | K24: {=XLOOKUP(C24,'Master Data'!C:C,'Master Data'!J:J)} | L24: {=XLOOKUP(C:C,TSR_Completion!C:C,TSR_Completion!M:M)} -> Completed and Issued | M24: Results Downloaded_Pooja
B25: Narayan | C25: 77000250398 | D25: {=XLOOKUP(C25,'Master Data'!C:C,'Master Data'!D:D)} -> Wakad | E25: 10.04.2026 | F25: {=XLOOKUP(C25,'Master Data'!C:C,'Master Data'!E:E)} -> Patansing Patlawat | G25: {=XLOOKUP(C25,'Master Data'!C:C,'Master Data'!F:F)} | H25: {=XLOOKUP(C25,'Master Data'!C:C,'Master Data'!G:G)} -> LAP | I25: {=XLOOKUP(C25,'Master Data'!C:C,'Master Data'!H:H)} -> Nande Pune S.No.35 | J25: {=XLOOKUP(C25,'Master Data'!C:C,'Master Data'!I:I)} | K25: {=XLOOKUP(C25,'Master Data'!C:C,'Master Data'!J:J)} | L25: {=XLOOKUP(C:C,TSR_Completion!C:C,TSR_Completion!M:M)} -> #N/A | M25: Done by Deepali
A26: 595 | B26: Narayan | C26: 77000256348 | D26: {=XLOOKUP(C26,'Master Data'!C:C,'Master Data'!D:D)} -> Main | E26: 15.04.2026 | F26: {=XLOOKUP(C26,'Master Data'!C:C,'Master Data'!E:E)} -> Mayur Shankar Amrale | G26: {=XLOOKUP(C26,'Master Data'!C:C,'Master Data'!F:F)} -> Kunal Shankar Amrale | H26: {=XLOOKUP(C26,'Master Data'!C:C,'Master Data'!G:G)} -> Case self contraction | I26: {=XLOOKUP(C26,'Master Data'!C:C,'Master Data'!H:H)} -> All that piece and parcel of property bearing CTS No. 41, having an area admeasuring of 164.31 sq. mtrs., situated at Village – Ambethan, Taluka – Khed, District – Pune. | J26: {=XLOOKUP(C26,'Master Data'!C:C,'Master Data'!I:I)} -> . | K26: {=XLOOKUP(C26,'Master Data'!C:C,'Master Data'!J:J)} | L26: {=XLOOKUP(C:C,TSR_Completion!C:C,TSR_Completion!M:M)} -> Completed and Issued | M26: Results Downloaded_Pooja
A27: 594 | B27: Narayan | C27: 77000254650 | D27: {=XLOOKUP(C27,'Master Data'!C:C,'Master Data'!D:D)} -> Wakad | E27: 14.04.2026 | F27: {=XLOOKUP(C27,'Master Data'!C:C,'Master Data'!E:E)} -> Bhagwandatta Varma | G27: {=XLOOKUP(C27,'Master Data'!C:C,'Master Data'!F:F)} -> Nirmala Varma | H27: {=XLOOKUP(C27,'Master Data'!C:C,'Master Data'!G:G)} -> Lap | I27: {=XLOOKUP(C27,'Master Data'!C:C,'Master Data'!H:H)} -> All that piece and parcel of the property being Flat No. 13, admeasuring 850 Sq. Ft. i.e. 78.99 Sq. Mtrs., situated on the Second Floor, in Wing “B” of Building “B”, in the building known as “Swapnanagari”, constructed on land bearing Gat Nos. 381, 382, 383, 384, 385, 386, 370, 390 and 484/3, admeasuring total non-agricultural area 44,476.91 Sq. Mtrs., situated at Village Chakan, Taluka Khed, District Pune, together with all rights, easements and appurtenances thereto. | J27: {=XLOOKUP(C27,'Master Data'!C:C,'Master Data'!I:I)} | K27: {=XLOOKUP(C27,'Master Data'!C:C,'Master Data'!J:J)} | L27: {=XLOOKUP(C:C,TSR_Completion!C:C,TSR_Completion!M:M)} -> Completed and Issued | M27: Results Downloaded_Pooja
A28: 639 | B28: Narayan | C28: 77000253700 | D28: {=XLOOKUP(C28,'Master Data'!C:C,'Master Data'!D:D)} -> Kolhapur | E28: 14.04.2026 | F28: {=XLOOKUP(C28,'Master Data'!C:C,'Master Data'!E:E)} -> Pawan Tukaram Bhosale | G28: {=XLOOKUP(C28,'Master Data'!C:C,'Master Data'!F:F)} -> Sharada Tukaram Bhosale | H28: {=XLOOKUP(C28,'Master Data'!C:C,'Master Data'!G:G)} -> Resale Purchase - Apana Ghar Regular | I28: {=XLOOKUP(C28,'Master Data'!C:C,'Master Data'!H:H)} -> All that piece and parcel of Flat No. 201, admeasuring 47.08 Sq. Mtrs. carpet area and 62.45 Sq. Mtrs. super built-up area, situated on the Second Floor of the building known as “Tulip Buds”, constructed on land bearing R.S. No. 529/1, T.P. Scheme No. 3, Final Plot No. 30 (Part), situated at Kasba Karveer, Taluka Karveer, ‘E’ Ward, Kolhapur. | J28: {=XLOOKUP(C28,'Master Data'!C:C,'Master Data'!I:I)} | K28: {=XLOOKUP(C28,'Master Data'!C:C,'Master Data'!J:J)} | L28: {=XLOOKUP(C:C,TSR_Completion!C:C,TSR_Completion!M:M)} -> Completed and Issued | M28: Results Downloaded _Deepali
A29: 596 | B29: Narayan | C29: 77000232406 | D29: {=XLOOKUP(C29,'Master Data'!C:C,'Master Data'!D:D)} -> Baner | E29: 14.04.2026 | F29: {=XLOOKUP(C29,'Master Data'!C:C,'Master Data'!E:E)} -> Saumya Umeshkumar Trivedi | G29: {=XLOOKUP(C29,'Master Data'!C:C,'Master Data'!F:F)} | H29: {=XLOOKUP(C29,'Master Data'!C:C,'Master Data'!G:G)} -> HL Resale | I29: {=XLOOKUP(C29,'Master Data'!C:C,'Master Data'!H:H)} -> All that piece and parcel of the Flat No. 601, admeasuring Carpet Area 41.17 Sq. Mtrs. i.e. 443 Sq. Ft. along with additional saleable terrace area admeasuring 3.25 Sq. Mtrs. i.e. 35 Sq. Ft., situated on the Sixth Floor of Wing “H” in the project known as “Akruti Countrywoods”, constructed on land bearing Survey Nos. 45/1/1, 45/1/4, 45/1/4/1, 45/1/4/6, 45/1/4/8A, 45/2/1, 45/2/2, 45/3/1, 45/3/2, 45/3/3, 45/3/9, 45/3/11, 45/3/14 (part), 45/3/15, 45/3/16, 45/3/17, 45/3/18, 45/4/1, 45/4/2 (part), 45/5/1, 45/5/2, 45/5/4, 45/5/5 and its sub-divisions, 45/5/6, 45/5/7, 45/5/9, 45/5/13, 45/5/15, 45/5/16, 45/6/1 (part), 45/6/2, 45/6/3, 45/6/4 and its sub-divisions, 45/6/5, 45/6/6, 45/7/1, 45/7/2, 45/7/3, 45/7/4, 45/7/5 and its sub-divisions, 45/7/6 (part), 45/7/7, 45/7/8 and its sub-divisions, 45/7/9 and its sub-divisions, 45/3/10, 45/3/12, 45/3/13, 45/3/19, 45/3/20, 45/3/21, 45/3/22 and its sub-divisions, 45/5/3, 45/5/8, 45/5/10, 45/5/11, 45/5/12 and its sub-divisions, 45/5/14, together admeasuring in aggregate about 17 Hectares 29.3386 Ares i.e. 172,933.86 Sq. Mtrs., out of which land admeasuring 54,339.99 Sq. Mtrs. is developed for the said project, situated at Village Kondhwa Budruk, Taluka Haveli, District Pune, within the limits of Pune Municipal Corporation, together with all rights, easements and appurtenances attached thereto. | J29: {=XLOOKUP(C29,'Master Data'!C:C,'Master Data'!I:I)} | K29: {=XLOOKUP(C29,'Master Data'!C:C,'Master Data'!J:J)} | L29: {=XLOOKUP(C:C,TSR_Completion!C:C,TSR_Completion!M:M)} -> Completed and Issued | M29: Done by Deepali
A30: 598 | B30: Narayan | C30: 77000236583 | D30: {=XLOOKUP(C30,'Master Data'!C:C,'Master Data'!D:D)} -> Main | E30: 15.04.2026 | F30: {=XLOOKUP(C30,'Master Data'!C:C,'Master Data'!E:E)} -> waman jadhav | G30: {=XLOOKUP(C30,'Master Data'!C:C,'Master Data'!F:F)} -> mahananda jadhav | H30: {=XLOOKUP(C30,'Master Data'!C:C,'Master Data'!G:G)} -> resale( seller BT) | I30: {=XLOOKUP(C30,'Master Data'!C:C,'Master Data'!H:H)} -> All that piece and parcel of the Flat No. 1, admeasuring 48.60 Sq. Mtrs., together with adjoining terrace admeasuring 46 Sq. Ft. i.e. 4.27 Sq. Mtrs. (built-up), situated on the First Floor of the building known as “Pratibha Apartment”, constructed on land bearing Survey Nos. 23, 24, 55, 57 and 58 corresponding to City Survey No. 23, out of Plot No. 80, situated at Village Karvenagar, Taluka Haveli, District Pune. | J30: {=XLOOKUP(C30,'Master Data'!C:C,'Master Data'!I:I)} | K30: {=XLOOKUP(C30,'Master Data'!C:C,'Master Data'!J:J)} | L30: {=XLOOKUP(C:C,TSR_Completion!C:C,TSR_Completion!M:M)} -> Completed and Issued | M30: Results Downloaded_Pooja
A31: 591 | B31: Narayan | C31: 77000244624 | D31: {=XLOOKUP(C31,'Master Data'!C:C,'Master Data'!D:D)} -> Baner | E31: 10.04.2026 | F31: {=XLOOKUP(C31,'Master Data'!C:C,'Master Data'!E:E)} -> Rekha Ankush Kongale | G31: {=XLOOKUP(C31,'Master Data'!C:C,'Master Data'!F:F)} -> Ankush Vyankat Kongale | H31: Resale Purchase | I31: {=XLOOKUP(C31,'Master Data'!C:C,'Master Data'!H:H)} -> All that piece and parcel of the residential premises being Flat No. 705, situated at Seventh Floor, admeasuring about 427.87 Sq. ft. = 39.76 Sq. mtrs. carpet alongwith balcony admeasuring about 50.26 Sq. ft. = 4.67 Sq. mtrs. thus total admeasuring about 478.13 Sq. ft. = 44.42 Sq. mtrs. in the building of Nakshatra Residency Cooperative Housing Society Ltd. constructed on land Survey No. 43, Hissa No. 7/2A/1/1 and Survey No. 43, Hissa No. 7/2B, situated at Village Katraj, Taluka Haveli, District Pune and within local limits of Pune Municipal Corportion, Pune. | J31: {=XLOOKUP(C31,'Master Data'!C:C,'Master Data'!I:I)} -> . | K31: {=XLOOKUP(C31,'Master Data'!C:C,'Master Data'!J:J)} | L31: {=XLOOKUP(C:C,TSR_Completion!C:C,TSR_Completion!M:M)} -> Completed and Issued | M31: Results Downloaded_Pooja
A32: 606 | B32: Narayan | C32: 77000242496 | D32: {=XLOOKUP(C32,'Master Data'!C:C,'Master Data'!D:D)} -> Kharadi | E32: 16.04.2026 | F32: {=XLOOKUP(C32,'Master Data'!C:C,'Master Data'!E:E)} -> Sambhaji Vasant Choudhary | G32: {=XLOOKUP(C32,'Master Data'!C:C,'Master Data'!F:F)} | H32: {=XLOOKUP(C32,'Master Data'!C:C,'Master Data'!G:G)} -> Plot + Contruction | I32: {=XLOOKUP(C32,'Master Data'!C:C,'Master Data'!H:H)} -> All that piece and parcel of non-agricultural property admeasuring of H. 00-04 Ares, out of Gat No. 991, having an area admeasuring of H. 01-32 Ares, assessed at Rs. 03-06 Paise, situated at Village – Ranjangao Ganpati, Taluka – Shirur, District – Pune | J32: {=XLOOKUP(C32,'Master Data'!C:C,'Master Data'!I:I)} | K32: {=XLOOKUP(C32,'Master Data'!C:C,'Master Data'!J:J)} | L32: {=XLOOKUP(C:C,TSR_Completion!C:C,TSR_Completion!M:M)} -> Completed and Issued | M32: Results Downloaded_Pooja
A33: 607 | B33: Narayan | C33: 364010445963 | D33: {=XLOOKUP(C33,'Master Data'!C:C,'Master Data'!D:D)} -> Kolhapur | E33: 16.04.2026 | F33: {=XLOOKUP(C33,'Master Data'!C:C,'Master Data'!E:E)} -> Virendra Krushnat Patil | G33: {=XLOOKUP(C33,'Master Data'!C:C,'Master Data'!F:F)} -> Nil | H33: {=XLOOKUP(C33,'Master Data'!C:C,'Master Data'!G:G)} -> home loan | I33: {=XLOOKUP(C33,'Master Data'!C:C,'Master Data'!H:H)} -> All that piece and parcel of property admeasuring of 31.66 sq. mtrs., out of non-agricultural property bearing CTS No. 2874, having an area admeasuring of 47.5 sq. mtrs., situated at Village – Kodoli, Taluka – Panhala, District Kolhapur. | J33: {=XLOOKUP(C33,'Master Data'!C:C,'Master Data'!I:I)} -> . | K33: {=XLOOKUP(C33,'Master Data'!C:C,'Master Data'!J:J)} | L33: {=XLOOKUP(C:C,TSR_Completion!C:C,TSR_Completion!M:M)} -> Completed and Issued | M33: Results Downloaded_Pooja
A34: 592 | B34: Narayan | C34: 77000255667 | D34: {=XLOOKUP(C34,'Master Data'!C:C,'Master Data'!D:D)} -> Vishrantwadi | E34: 10.04.2026 | F34: {=XLOOKUP(C34,'Master Data'!C:C,'Master Data'!E:E)} -> Rushi kale | G34: {=XLOOKUP(C34,'Master Data'!C:C,'Master Data'!F:F)} -> Gorakh kale | H34: {=XLOOKUP(C34,'Master Data'!C:C,'Master Data'!G:G)} -> Lap | I34: {=XLOOKUP(C34,'Master Data'!C:C,'Master Data'!H:H)} -> Hadapsar S.No. 231 | J34: {=XLOOKUP(C34,'Master Data'!C:C,'Master Data'!I:I)} -> 7040506640(SIR) | K34: {=XLOOKUP(C34,'Master Data'!C:C,'Master Data'!J:J)} | L34: {=XLOOKUP(C:C,TSR_Completion!C:C,TSR_Completion!M:M)} -> #N/A | M34: Joint/Undivided property
A35: 593 | B35: Narayan | C35: 77000244340 | D35: {=XLOOKUP(C35,'Master Data'!C:C,'Master Data'!D:D)} -> Kolhapur | E35: 10.04.2026 | F35: {=XLOOKUP(C35,'Master Data'!C:C,'Master Data'!E:E)} -> Kedar Narayan Khandagale | G35: {=XLOOKUP(C35,'Master Data'!C:C,'Master Data'!F:F)} -> Surekha Narayan Khandagle | H35: {=XLOOKUP(C35,'Master Data'!C:C,'Master Data'!G:G)} -> Home Loan Resale | I35: {=XLOOKUP(C35,'Master Data'!C:C,'Master Data'!H:H)} -> Kandal Gaon Kolhapur S.No. 106 | J35: {=XLOOKUP(C35,'Master Data'!C:C,'Master Data'!I:I)} | K35: {=XLOOKUP(C35,'Master Data'!C:C,'Master Data'!J:J)} | L35: {=XLOOKUP(C:C,TSR_Completion!C:C,TSR_Completion!M:M)} -> #N/A | M35: Results downloaded
A36: 597 | B36: Narayan | C36: 7792132614 | D36: {=XLOOKUP(C36,'Master Data'!C:C,'Master Data'!D:D)} -> Kharadi | E36: 13.04.2026 | F36: {=XLOOKUP(C36,'Master Data'!C:C,'Master Data'!E:E)} -> Makuniversal Infratech India Private Limited | G36: {=XLOOKUP(C36,'Master Data'!C:C,'Master Data'!F:F)} -> piyush pandit ,nandkumar pandit ,jyoti pandit | H36: {=XLOOKUP(C36,'Master Data'!C:C,'Master Data'!G:G)} -> LAP case | I36: {=XLOOKUP(C36,'Master Data'!C:C,'Master Data'!H:H)} | J36: {=XLOOKUP(C36,'Master Data'!C:C,'Master Data'!I:I)} -> 9112040427 (NLK Mobile) | K36: {=XLOOKUP(C36,'Master Data'!C:C,'Master Data'!J:J)} | L36: {=XLOOKUP(C:C,TSR_Completion!C:C,TSR_Completion!M:M)} -> #N/A
B37: Narayan | C37: 77000251190_1 | D37: {=XLOOKUP(C37,'Master Data'!C:C,'Master Data'!D:D)} -> Baner | E37: 04.04.2026 | F37: {=XLOOKUP(C37,'Master Data'!C:C,'Master Data'!E:E)} -> VRINDA MANISH BUTTAN | G37: {=XLOOKUP(C37,'Master Data'!C:C,'Master Data'!F:F)} | H37: {=XLOOKUP(C37,'Master Data'!C:C,'Master Data'!G:G)} -> BT Top UP | I37: {=XLOOKUP(C37,'Master Data'!C:C,'Master Data'!H:H)} -> All that residential Flat/Apartment No. 701, admeasuring 92.44 Sq. Mtrs. (i.e. approximately 995.01 Sq. Feet), situated on the 7th Floor, in “D” Building of the project known as “Maestros”, constructed on land bearing Survey No. 60/7, situated at Village – Wanawadi (Wanorie), Taluka – Haveli, District – Pune, within the limits of Pune Municipal Corporation, along with the right to use one car parking space, together with all easements, rights and appurtenances thereto. | J37: {=XLOOKUP(C37,'Master Data'!C:C,'Master Data'!I:I)} -> 99 | K37: {=XLOOKUP(C37,'Master Data'!C:C,'Master Data'!J:J)} | L37: {=XLOOKUP(C:C,TSR_Completion!C:C,TSR_Completion!M:M)} -> Completed and Issued
B38: Narayan | C38: 77000251190_2 | D38: {=XLOOKUP(C38,'Master Data'!C:C,'Master Data'!D:D)} -> Baner | E38: 04.04.2026 | F38: {=XLOOKUP(C38,'Master Data'!C:C,'Master Data'!E:E)} -> VRINDA MANISH BUTTAN | G38: {=XLOOKUP(C38,'Master Data'!C:C,'Master Data'!F:F)} | H38: {=XLOOKUP(C38,'Master Data'!C:C,'Master Data'!G:G)} -> BT Top UP | I38: {=XLOOKUP(C38,'Master Data'!C:C,'Master Data'!H:H)} -> All that residential Flat/Apartment No. 701-B, admeasuring 88.72 Sq. Mtrs. (i.e. approximately 955.00 Sq. Feet), situated on the 7th Floor, in “D” Building of the project known as “Maestros”, constructed on land bearing Survey No. 60/7, situated at Village – Wanawadi (Wanorie), Taluka – Haveli, District – Pune, within the limits of Pune Municipal Corporation, together with undivided share of 0.190% in the land, along with all easements, rights and appurtenances thereto. | J38: {=XLOOKUP(C38,'Master Data'!C:C,'Master Data'!I:I)} -> 99 | K38: {=XLOOKUP(C38,'Master Data'!C:C,'Master Data'!J:J)} | L38: {=XLOOKUP(C:C,TSR_Completion!C:C,TSR_Completion!M:M)} -> Completed and Issued
B39: Narayan | C39: 77000251190_3 | D39: {=XLOOKUP(C39,'Master Data'!C:C,'Master Data'!D:D)} -> Baner | E39: 04.04.2026 | F39: {=XLOOKUP(C39,'Master Data'!C:C,'Master Data'!E:E)} -> VRINDA MANISH BUTTAN | G39: {=XLOOKUP(C39,'Master Data'!C:C,'Master Data'!F:F)} | H39: {=XLOOKUP(C39,'Master Data'!C:C,'Master Data'!G:G)} -> BT Top UP | I39: {=XLOOKUP(C39,'Master Data'!C:C,'Master Data'!H:H)} -> All that residential Flat/Apartment No. 801, admeasuring 88.26 Sq. Mtrs. (i.e. approximately 949.91 Sq. Feet), situated on the 8th Floor, in “D” Building of the project known as “Maestros”, constructed on land bearing Survey No. 60/7, situated at Village – Wanawadi (Wanorie), Taluka – Haveli, District – Pune, within the limits of Pune Municipal Corporation, together with adjoining terrace and terrace appurtenant to the said flat admeasuring in aggregate 157.93 Sq. Mtrs., along with undivided share of 0.190% in the land, together with all easements, rights and appurtenances thereto. | J39: {=XLOOKUP(C39,'Master Data'!C:C,'Master Data'!I:I)} -> 99 | K39: {=XLOOKUP(C39,'Master Data'!C:C,'Master Data'!J:J)} | L39: {=XLOOKUP(C:C,TSR_Completion!C:C,TSR_Completion!M:M)} -> Completed and Issued
